<?xml version="1.0"?>
<robot name="dif_bot" xmlns:xacro="http://www.ros.org/wiki/xacro">

  <xacro:property name="base_length" value="0.45"/>
  <xacro:property name="base_width" value="0.30"/>
  <xacro:property name="base_height" value="0.12"/>

  <xacro:property name="wheel_radius" value="0.07"/>
  <xacro:property name="wheel_width" value="0.04"/>
  <xacro:property name="wheel_offset_y" value="0.18"/>
  <xacro:property name="wheel_offset_x" value="0.05"/>

  <xacro:property name="caster_radius" value="0.035"/>
  <xacro:property name="caster_offset_x" value="-0.17"/>
  <xacro:property name="caster_offset_z" value="-0.06"/>

  <link name="base_footprint"/>

  <link name="base_link">
    <visual>
      <origin xyz="0 0 ${base_height/2}" rpy="0 0 0"/>
      <geometry>
        <box size="${base_length} ${base_width} ${base_height}"/>
      </geometry>
      <material name="blue">
        <color rgba="0.1 0.2 0.8 1"/>
      </material>
    </visual>
  </link>

  <joint name="base_footprint_joint" type="fixed">
    <parent link="base_footprint"/>
    <child link="base_link"/>
    <origin xyz="0 0 0" rpy="0 0 0"/>
  </joint>

  <xacro:macro name="wheel" params="name y_pos">
    <link name="${name}">
      <visual>
        <origin xyz="0 0 0" rpy="1.5708 0 0"/>
        <geometry>
          <cylinder radius="${wheel_radius}" length="${wheel_width}"/>
        </geometry>
        <material name="black">
          <color rgba="0.02 0.02 0.02 1"/>
        </material>
      </visual>
    </link>

    <joint name="${name}_joint" type="continuous">
      <parent link="base_link"/>
      <child link="${name}"/>
      <origin xyz="${wheel_offset_x} ${y_pos} ${wheel_radius}" rpy="0 0 0"/>
      <axis xyz="0 1 0"/>
    </joint>
  </xacro:macro>

  <xacro:wheel name="left_wheel" y_pos="${wheel_offset_y}"/>
  <xacro:wheel name="right_wheel" y_pos="${-wheel_offset_y}"/>

  <link name="caster_wheel">
    <visual>
      <geometry>
        <sphere radius="${caster_radius}"/>
      </geometry>
      <material name="gray">
        <color rgba="0.5 0.5 0.5 1"/>
      </material>
    </visual>
  </link>

  <joint name="caster_joint" type="fixed">
    <parent link="base_link"/>
    <child link="caster_wheel"/>
    <origin xyz="${caster_offset_x} 0 ${caster_offset_z + caster_radius}" rpy="0 0 0"/>
  </joint>

</robot>
