<?xml version="1.0"?>
<robot name="dif_bot" xmlns:xacro="http://www.ros.org/wiki/xacro">
  <xacro:include filename="$(find dif_bot_description)/urdf/sensors.xacro"/>
  <!-- Propiedades -->
  <xacro:property name="base_width" value="0.31"/>
  <xacro:property name="base_length" value="0.42"/>
  <xacro:property name="base_height" value="0.18"/>

  <xacro:property name="wheel_radius" value="0.10"/>
  <xacro:property name="wheel_width" value="0.04"/>
  <xacro:property name="wheel_ygap" value="0.025"/>
  <xacro:property name="wheel_zoff" value="0.05"/>
  <xacro:property name="wheel_xoff" value="0.12"/>

  <xacro:property name="caster_xoff" value="0.14"/>
  <xacro:property name="caster_radius" value="0.035"/>

  <!-- Masas -->
  <xacro:property name="base_mass" value="5.0"/>
  <xacro:property name="wheel_mass" value="0.5"/>
  <xacro:property name="caster_mass" value="0.2"/>

  <!-- Macro inercia caja -->
  <xacro:macro name="box_inertia" params="m x y z">
    <inertial>
      <mass value="${m}"/>
     <inertia
        ixx="${(1/12) * m * (y*y + z*z)}"
        ixy="0.0"
        ixz="0.0"
        iyy="${(1/12) * m * (x*x + z*z)}"
        iyz="0.0"
        izz="${(1/12) * m * (x*x + y*y)}"/>
    </inertial>
  </xacro:macro>

  <!-- Macro inercia cilindro -->
  <xacro:macro name="cylinder_inertia" params="m r h">
    <inertial>
      <mass value="${m}"/>
      <inertia
        ixx="${(1/12) * m * (3*r*r + h*h)}"
        ixy="0.0"
        ixz="0.0"
        iyy="${(1/12) * m * (3*r*r + h*h)}"
        iyz="0.0"
        izz="${(1/2) * m * r*r}"/>
    </inertial>
  </xacro:macro>

  <!-- Macro inercia esfera -->
  <xacro:macro name="sphere_inertia" params="m r">
    <inertial>
      <mass value="${m}"/>
      <inertia
        ixx="${(2/5) * m * r*r}"
        ixy="0.0"
        ixz="0.0"
        iyy="${(2/5) * m * r*r}"
        iyz="0.0"
        izz="${(2/5) * m * r*r}"/>
    </inertial>
  </xacro:macro>

  <!-- base_footprint -->
  <link name="base_footprint"/>

  <joint name="base_footprint_joint" type="fixed">
    <parent link="base_footprint"/>
    <child link="base_link"/>
    <origin xyz="0 0 0.15" rpy="0 0 0"/>
  </joint>

  <!-- base_link -->
  <link name="base_link">
    <visual>
      <geometry>
        <box size="${base_length} ${base_width} ${base_height}"/>
      </geometry>
      <material name="cyan">
        <color rgba="0 0.8 1 1"/>
      </material>
    </visual>

    <collision>
      <geometry>
        <box size="${base_length} ${base_width} ${base_height}"/>
      </geometry>
    </collision>

    <xacro:box_inertia m="${base_mass}" x="${base_length}" y="${base_width}" z="${base_height}"/>
  </link>

  <!-- Macro para ruedas -->
  <xacro:macro name="wheel" params="name y_pos">
    <link name="${name}">
      <visual>
        <origin xyz="0 0 0" rpy="1.5708 0 0"/>
        <geometry>
          <cylinder radius="${wheel_radius}" length="${wheel_width}"/>
        </geometry>
        <material name="gray">
          <color rgba="0.45 0.45 0.45 1"/>
        </material>
      </visual>

      <collision>
        <origin xyz="0 0 0" rpy="1.5708 0 0"/>
        <geometry>
          <cylinder radius="${wheel_radius}" length="${wheel_width}"/>
        </geometry>
      </collision>

      <xacro:cylinder_inertia m="${wheel_mass}" r="${wheel_radius}" h="${wheel_width}"/>
    </link>

    <joint name="${name}_joint" type="continuous">
      <parent link="base_link"/>
      <child link="${name}"/>
      <origin xyz="${-wheel_xoff} ${y_pos} ${-wheel_zoff}" rpy="0 0 0"/>
      <axis xyz="0 1 0"/>
    </joint>
  </xacro:macro>

  <!-- Ruedas -->
  <xacro:wheel name="left_wheel" y_pos="${base_width/2 + wheel_ygap}"/>
  <xacro:wheel name="right_wheel" y_pos="${-(base_width/2 + wheel_ygap)}"/>

  <!-- Caster delantero -->
  <link name="front_caster">
 <visual>
      <geometry>
        <sphere radius="${caster_radius}"/>
      </geometry>
      <material name="black">
        <color rgba="0.05 0.05 0.05 1"/>
      </material>
    </visual>

    <collision>
      <geometry>
        <sphere radius="${caster_radius}"/>
      </geometry>
    </collision>

    <xacro:sphere_inertia m="${caster_mass}" r="${caster_radius}"/>
  </link>

  <joint name="front_caster_joint" type="fixed">
    <parent link="base_link"/>
    <child link="front_caster"/>
    <origin xyz="${caster_xoff} 0 ${-(base_height/2)}" rpy="0 0 0"/>
  </joint>
  <!-- Gazebo Diff Drive Plugin -->
  <gazebo>
    <plugin
      filename="gz-sim-diff-drive-system"
      name="gz::sim::systems::DiffDrive">

      <left_joint>right_wheel_joint</left_joint>
      <right_joint>left_wheel_joint</right_joint>

      <wheel_separation>0.36</wheel_separation>
      <wheel_radius>0.10</wheel_radius>

      <topic>cmd_vel</topic>
      <odom_topic>odom</odom_topic>
      <frame_id>odom</frame_id>
      <child_frame_id>base_footprint</child_frame_id>

    </plugin>
  </gazebo>
  <!-- Sensores -->
</robot>


